Workbook
Name _Row2: Data!$L$16:$L$40
Name Capacity: Data!$A:$A
Name Curve: Data!#REF!
Name DirCost: Data!$E:$E
Name DP: Data!$B:$B
Name DPselect: Data!$N$16:$N$40
Name end: Data!#REF!
Name EndRow: Data!$M$8
Name EqCost: Data!$D:$D
Name last: Data!$I:$I
Name Material: Data!$C:$C
Name Material2: Data!$M$16:$M$40
Name MaterialEndRow: Data!#REF!
Name MaterialStartRow: Data!#REF!
Name range: Data!$G:$G
Name RequiredCapacity: Specification!$D$2
Name SpecDP: Specification!$D$4
Name SpecMaterial: Specification!$D$3
Name Start: Data!$H:$H
Name startrow: Data!$M$7

Sheet Specification
A1: Required
B2: Required Volume | D2: 4000 | E2: gallons
B3: Material | D3: A204C | G3: Adjust the required parameters in blue and the cost model (data tab) will make the available calculations (below)
B4: DP | D4: 300 | E4: psig
A7: Available
B8: Volume | D8: =INDEX(Capacity,INDEX(_Row2,MATCH(SpecDP,DPselect,-1))) -> 5000 | E8: =E2 -> gallons
B9: Material | D9: =INDEX(Material,INDEX(_Row2,MATCH(SpecDP,DPselect,-1))) -> A204C | G9: These available parameters are calculated based on the required input (above)
B10: Design Pressure | D10: =INDEX(DP,INDEX(_Row2,MATCH(SpecDP,DPselect,-1))) -> 400 | E10: =E4 -> psig
B11: Equipment Cost | D11: =INDEX(EqCost,INDEX(_Row2,MATCH(SpecDP,DPselect,-1))) -> 177800
B12: Direct Cost | D12: =INDEX(DirCost,INDEX(_Row2,MATCH(SpecDP,DPselect,-1))) -> 300700

Sheet Data
G1: Enter Starting and ending rows:
A2: Capacity (Gallons) | B2: DP (psig) | C2: Material | D2: Equipment Cost (US$) | E2: Direct Cost (US$) | G2: Capacity | H2: start row | I2: end row
A3: 8000 | B3: 500 | C3: A285C | D3: 209600 | E3: 356400 | G3: 8000 | H3: 3 | I3: 20 | L3: Which rows contain data for the spec capacity?
A4: 8000 | B4: 400 | C4: A285C | D4: 192800 | E4: 339100 | G4: 5000 | H4: 21 | I4: 38 | L4: rows containing capacity
A5: 8000 | B5: 250 | C5: A285C | D5: 169600 | E5: 315300 | G5: 3200 | H5: 39 | I5: 56 | L5: index | M5: =MATCH(RequiredCapacity,Capacity,-1) -> 38
A6: 8000 | B6: 150 | C6: A285C | D6: 164200 | E6: 309800 | G6: 1500 | H6: 57 | I6: 74 | L6: capacity | M6: =INDEX(Capacity,M5) -> 5000
A7: 8000 | B7: 100 | C7: A285C | D7: 160200 | E7: 304700 | L7: start row | M7: =INDEX(Start,MATCH(M6,range,-1)) -> 21
A8: 8000 | B8: 50 | C8: A285C | D8: 160200 | E8: 304700 | L8: end row | M8: =INDEX(last,MATCH(M6,range,-1)) -> 38
A9: 8000 | B9: 500 | C9: A204C | D9: 237000 | E9: 377100
A10: 8000 | B10: 400 | C10: A204C | D10: 225000 | E10: 364800
A11: 8000 | B11: 250 | C11: A204C | D11: 214200 | E11: 353700
A12: 8000 | B12: 150 | C12: A204C | D12: 205500 | E12: 344000
A13: 8000 | B13: 100 | C13: A204C | D13: 205500 | E13: 344000 | L13: Which capacity rows match SpecMaterial?
A14: 8000 | B14: 50 | C14: A204C | D14: 205500 | E14: 344000 | L14: rows containing material
A15: 8000 | B15: 500 | C15: GSLCS | D15: 252100 | E15: 487700 | L15: Row | M15: Material | N15: DP
A16: 8000 | B16: 400 | C16: GSLCS | D16: 238200 | E16: 472000 | L16: =startrow -> 21 | M16: =IF( L16<=EndRow,(IF(INDEX(Material,L16)=SpecMaterial,INDEX(Material,L16)," "))," ") | N16: =IF(NOT(M16=" "),INDEX(DP,L16)," ")
A17: 8000 | B17: 250 | C17: GSLCS | D17: 205800 | E17: 438900 | L17: =L16+1 -> 22 | M17: =IF( L17<=EndRow,(IF(INDEX(Material,L17)=SpecMaterial,INDEX(Material,L17)," "))," ") | N17: =IF(NOT(M17=" "),INDEX(DP,L17)," ")
A18: 8000 | B18: 200 | C18: GSLCS | D18: 199600 | E18: 426900 | L18: =L17+1 -> 23 | M18: =IF( L18<=EndRow,(IF(INDEX(Material,L18)=SpecMaterial,INDEX(Material,L18)," "))," ") | N18: =IF(NOT(M18=" "),INDEX(DP,L18)," ")
A19: 8000 | B19: 150 | C19: GSLCS | D19: 196400 | E19: 423500 | L19: =L18+1 -> 24 | M19: =IF( L19<=EndRow,(IF(INDEX(Material,L19)=SpecMaterial,INDEX(Material,L19)," "))," ") | N19: =IF(NOT(M19=" "),INDEX(DP,L19)," ")
A20: 8000 | B20: 50 | C20: GSLCS | D20: 196400 | E20: 423500 | L20: =L19+1 -> 25 | M20: =IF( L20<=EndRow,(IF(INDEX(Material,L20)=SpecMaterial,INDEX(Material,L20)," "))," ") | N20: =IF(NOT(M20=" "),INDEX(DP,L20)," ")
A21: 5000 | B21: 500 | C21: A285C | D21: 166000 | E21: 295000 | L21: =L20+1 -> 26 | M21: =IF( L21<=EndRow,(IF(INDEX(Material,L21)=SpecMaterial,INDEX(Material,L21)," "))," ") | N21: =IF(NOT(M21=" "),INDEX(DP,L21)," ")
A22: 5000 | B22: 400 | C22: A285C | D22: 153000 | E22: 281500 | L22: =L21+1 -> 27 | M22: =IF( L22<=EndRow,(IF(INDEX(Material,L22)=SpecMaterial,INDEX(Material,L22)," "))," ") -> A204C | N22: =IF(NOT(M22=" "),INDEX(DP,L22)," ") -> 500
A23: 5000 | B23: 250 | C23: A285C | D23: 137000 | E23: 265100 | L23: =L22+1 -> 28 | M23: =IF( L23<=EndRow,(IF(INDEX(Material,L23)=SpecMaterial,INDEX(Material,L23)," "))," ") -> A204C | N23: =IF(NOT(M23=" "),INDEX(DP,L23)," ") -> 400
A24: 5000 | B24: 150 | C24: A285C | D24: 133500 | E24: 261600 | L24: =L23+1 -> 29 | M24: =IF( L24<=EndRow,(IF(INDEX(Material,L24)=SpecMaterial,INDEX(Material,L24)," "))," ") -> A204C | N24: =IF(NOT(M24=" "),INDEX(DP,L24)," ") -> 250
A25: 5000 | B25: 100 | C25: A285C | D25: 130600 | E25: 257800 | L25: =L24+1 -> 30 | M25: =IF( L25<=EndRow,(IF(INDEX(Material,L25)=SpecMaterial,INDEX(Material,L25)," "))," ") -> A204C | N25: =IF(NOT(M25=" "),INDEX(DP,L25)," ") -> 150
A26: 5000 | B26: 50 | C26: A285C | D26: 130600 | E26: 257800 | L26: =L25+1 -> 31 | M26: =IF( L26<=EndRow,(IF(INDEX(Material,L26)=SpecMaterial,INDEX(Material,L26)," "))," ") -> A204C | N26: =IF(NOT(M26=" "),INDEX(DP,L26)," ") -> 100
A27: 5000 | B27: 500 | C27: A204C | D27: 186900 | E27: 310000 | L27: =L26+1 -> 32 | M27: =IF( L27<=EndRow,(IF(INDEX(Material,L27)=SpecMaterial,INDEX(Material,L27)," "))," ") -> A204C | N27: =IF(NOT(M27=" "),INDEX(DP,L27)," ") -> 50
A28: 5000 | B28: 400 | C28: A204C | D28: 177800 | E28: 300700 | L28: =L27+1 -> 33 | M28: =IF( L28<=EndRow,(IF(INDEX(Material,L28)=SpecMaterial,INDEX(Material,L28)," "))," ") | N28: =IF(NOT(M28=" "),INDEX(DP,L28)," ")
... A40: 3200 | B40: 400 | C40: A285C | D40: 119300 | E40: 243000 | L40: =L39+1 -> 45 | M40: =IF( L40<=EndRow,(IF(INDEX(Material,L40)=SpecMaterial,INDEX(Material,L40)," "))," ") | N40: =IF(NOT(M40=" "),INDEX(DP,L40)," ")
A41: 3200 | B41: 250 | C41: A285C | D41: 103900 | E41: 227300
A42: 3200 | B42: 150 | C42: A285C | D42: 50000 | E42: 120000
A43: 3200 | B43: 100 | C43: A285C | D43: 104400 | E43: 227700
A44: 3200 | B44: 50 | C44: A285C | D44: 102400 | E44: 224900
A45: 3200 | B45: 500 | C45: A204C | D45: 143800 | E45: 262400
A46: 3200 | B46: 400 | C46: A204C | D46: 137100 | E46: 255500
A47: 3200 | B47: 250 | C47: A204C | D47: 132000 | E47: 250200
A48: 3200 | B48: 150 | C48: A204C | D48: 127700 | E48: 245200
A49: 3200 | B49: 100 | C49: A204C | D49: 127700 | E49: 245200
A50: 3200 | B50: 50 | C50: A204C | D50: 127700 | E50: 245200
A51: 3200 | B51: 500 | C51: GSLCS | D51: 147200 | E51: 331400
...

Sheet Input
B1: User Model Input Template
B3: Project Component Type
B4: Item Information | C4: Value | D4: Units
B5: Equipment Name

Sheet Output
B1: User Model Output Template
B3: Project Component Type
B4: Item Information | C4: Value | D4: Units
B5: Equipment Name | C5: =Input!C5 -> 0
B6: CPLIQUIDVOLUME | C6: =Specification!D8 -> 5000 | D6: =Specification!E8 -> gallons
B7: CPDESIGNGAUGEPRESSURE | C7: =Specification!D10 -> 400 | D7: =Specification!E10 -> psig
B8: CPSHELLMATERIAL | C8: =Specification!D9 -> A204C
B9: CPQUOTEDCOST | C9: =Specification!D11 -> 177800
