Workbook

Sheet Input
B1: This template has been designed to be used for a Separator with up to three input streams and two output streams. The calculations contained in this example are based on the default APEA IP project units, custom or metric units will require user conversions in this spreadsheet.
B2: User Model Input Template
B3: SEPARATOR
B4: Item Information | C4: Value
B5: Equipment Name
B40: Connection Stream Information | C40: Value | D40: Units | E40: Value | F40: Units | G40: Value | H40: Units | I40: Value | J40: Units | K40: Value | L40: Units
B41: Stream Name
B42: Stream Direction
B43: Vapor Fraction
B44: Molecular Weight
B45: Temperature | D45: F
B46: Pressure | D46: PSIG
B47: Total Mass Flow | D47: LB/H
B48: Vapor Mass Density | D48: PCF
B49: Vapor Mass Flow | D49: LB/H
B50: Vapor Volumetric Flow | D50: CFH
B51: Liquid Mass Density | D51: PCF
B52: Liquid Mass Flow | D52: LB/H
B53: Liquid Volumetric Flow | D53: CFM
C54: =C41 -> 0 | E54: =E41 -> 0 | G54: =G41 -> 0 | I54: =I41 -> 0 | K54: =K41 -> 0
B57: Note: vapor fraction is on weight basis

Sheet Diagram
B1: CUSTOMIZED Project Component
I5: =Input!B3 -> SEPARATOR
I6: Item Information | J6: Value
I7: Equipment Name | J7: =IF(Input!C5="","",Input!C5) | K7: =IF(Input!D5="","",Input!D5)
N14: Stream Name | Q14: =IF(HLOOKUP("Output",Input!C42:K43,2,FALSE)>0,HLOOKUP("Output",Input!C42:K54,13,FALSE),HLOOKUP(1,Input!C43:K54,12,TRUE)) -> #N/A
N15: Temperature | Q15: =IF(HLOOKUP("Output",Input!C42:K43,2,FALSE)>0,HLOOKUP("Output",Input!C42:K54,3,FALSE),HLOOKUP(1,Input!C43:K54,3,TRUE)) -> #N/A | R15: ='Custom Rules'!C6 -> Deg F
N16: Pressure | Q16: =IF(HLOOKUP("Output",Input!C42:K43,2,FALSE)>0,HLOOKUP("Output",Input!C42:K54,4,FALSE),HLOOKUP(1,Input!C43:K54,4,TRUE)) -> #N/A | R16: =Input!D46 -> PSIG
D17: Stream Name | G17: =IF(Input!C42="Input",Input!C41,"") | N17: Total Mass Flow | Q17: =IF(HLOOKUP("Output",Input!C42:K43,2,FALSE)>0,HLOOKUP("Output",Input!C42:K54,4,FALSE),HLOOKUP(1,Input!C43:K54,7,TRUE)) -> #N/A | R17: =Input!D47 -> LB/H
D18: Temperature | G18: =IF(Input!C45="","",Input!C45) | H18: ='Custom Rules'!C6 -> Deg F | N18: Vapor Density | Q18: ='Custom Rules'!B9 -> #N/A | R18: ='Custom Rules'!C9 -> lb/ft3
D19: Pressure | G19: =IF(Input!C46="","",Input!C46) | H19: =IF(Input!D46="","",Input!D46) -> PSIG
D20: Total Mass Flow | G20: =IF(Input!C47="","",Input!C47) | H20: =IF(Input!D47="","",Input!D47) -> LB/H
D21: Vapor Fraction | G21: =IF(Input!C43="","",Input!C43)
D25: Stream Name | G25: =IF(Input!E42="Input",Input!E41,"")
D26: Temperature | G26: =IF(Input!E42="Input",Input!E45,"") | H26: =IF(G26="","",'Custom Rules'!C6)
D27: Pressure | G27: =IF(Input!E42="Input",Input!E46,"") | H27: =IF(G27="","",Input!F46)
D28: Total Mass Flow | G28: =IF(Input!E42="Input",Input!E47,"") | H28: =IF(G28="","",Input!F47)
D29: Vapor Fraction | G29: =IF(Input!E42="Input",Input!E43,"")
D39: Stream Name | G39: =IF(Input!G42="Input",Input!G41,"") | H39: =IF(Input!F56="Input",Input!F55,"")
D40: Temperature | G40: =IF(Input!G42="Input",Input!G45,"") | H40: =IF(G40="","",'Custom Rules'!C6)
D41: Pressure | G41: =IF(Input!G42="Input",Input!G46,"") | H41: =IF(G41="","",Input!F46)
D42: Total Mass Flow | G42: =IF(Input!G42="Input",Input!G47,"") | H42: =IF(G42="","",Input!F47)
D43: Vapor Fraction | G43: =IF(Input!G42="Input",Input!G43,"") | N43: Stream Name | Q43: =IF(HLOOKUP("Output",Input!C42:K43,2,FALSE)=0,HLOOKUP("Output",Input!C42:K54,13,FALSE),HLOOKUP(1,Input!C43:K54,12,TRUE)) -> #N/A
N44: Temperature | Q44: =Q15 -> #N/A | R44: ='Custom Rules'!C6 -> Deg F
N45: Pressure | Q45: =Q16 -> #N/A | R45: =Input!D46 -> PSIG
N46: Total Mass Flow | Q46: =IF(HLOOKUP("Output",Input!C42:K43,2,FALSE)=0,HLOOKUP("Output",Input!C42:K54,11,FALSE),HLOOKUP(1,Input!C43:K54,11,TRUE)) -> #N/A | R46: =Input!D47 -> LB/H
N47: Liquid Density | Q47: ='Custom Rules'!B11 -> #N/A | R47: ='Custom Rules'!C11 -> lb/ft3

Sheet Custom Rules
A1: Rules for Calculating the Size of a Vertical Separator via APEA Custom Model
A2: Note: this custom model is intended to illustrate how to retrieve stream data from a process simulator and use that information to perform simplified sizing calculations to design a vertical vessel. It is not intended to match the sizing results from APEA. Nozzle Sizing is also included to demonstrate how nozzles can be defined for a vessel (using a custom model). However, once nozzles are defined, this will override any system generated default nozzles.
A3: Note: these calculations are based on a 2 phase system. If only a single phase (or if 3 phases) are present, consider other equipment design options.
A5: Summary of Stream Data from Input Sheet
A6: Max. Stream Temperature | B6: =IF((Input!D45="C"),(LARGE(Input!C45:L45,1)*1.8+32),LARGE(Input!C45:L45,1)) -> #NUM! | C6: Deg F
A7: Max. Stream Pressure | B7: =LARGE(Input!C46:L46,1) -> #NUM! | C7: psig
A8: Actual Outlet Vapor Volumetric Flowrate: | B8: =IF(HLOOKUP("Output",Input!C42:K53,9,FALSE)=0,HLOOKUP(1,Input!C43:K53,8,TRUE))/3600 -> #N/A | C8: ft3/s
A9: Outlet Vapor Density: | B9: =IF(HLOOKUP("Output",Input!C42:K53,7,FALSE)>0,HLOOKUP("Output",Input!C42:K53,7,FALSE),HLOOKUP(1,Input!C43:K53,6,TRUE)) -> #N/A | C9: lb/ft3
A10: Actual Outlet Liquid Volumetric Flowrate: | B10: =IF(HLOOKUP("Output",Input!C42:K53,12,FALSE)>0,HLOOKUP("Output",Input!C42:K53,12,FALSE),HLOOKUP(0,Input!C43:K53,11,FALSE))/60 -> #N/A | C10: ft3/s
A11: Outlet Liquid Density: | B11: =IF(HLOOKUP("Output",Input!C42:K53,10,FALSE)>0,HLOOKUP("Output",Input!C42:K53,10,FALSE),HLOOKUP(1,Input!C43:K53,9,TRUE)) -> #N/A | C11: lb/ft3
A14: Vertical Vessel Sizing with Mist Eliminator (Calculations based on Inch Pound Units using Souders and Brown correlation and various Rules of Thumb, reference GPSA)
A15: Diameter Calculation: Vt = K*((rl-rg)/rg)^0.5, where:
A16: Vt = | B16: terminal velocity necessary for particles to settle out from gas, ft/s
A17: K = | B17: empirical constant for separator sizing, ft/s
A18: rl = | B18: liquid phase density, lb/ft3
A19: rg = | B19: gas phase density, lb/ft3
A21: Determining Vessel Diameter | K21: Nozzle Sizing
A22: K Coefficient: | B22: 0.24 | C22: User supplied value dependent on system, service, design (e.g. w/wo Mist Eliminator) and experience. Use 0.24 as a conservative estimate in this example. | K22: Vapor Outlet | Q22: Liquid Outlet
A23: Max Allowable Vap Veloc, Vt= | B23: =B22*((B11-B9)/B9)^0.5 -> #N/A | C23: ft/s | L23: Max. Allow. Velocity = | M23: =50/(B9)^0.5 -> #N/A | N23: ft/s | R23: Max. Allow. Velocity = | S23: 3.3 | T23: ft/s
A24: Min. Required Area, Ap = | B24: =B8/B23 -> #N/A | C24: ft2 | L24: Min. cross-sect Area = | M24: =B8/M23 -> #N/A | N24: ft2 | R24: Min. cross-sect Area = | S24: =B10/S23 -> #N/A | T24: ft2
A25: Min. Vessel Diameter, Dp = | B25: =(4*B24/PI())^0.5 -> #N/A | C25: ft | L25: Diameter = | M25: =(4*M24/PI())^0.5 -> #N/A | N25: ft | R25: Diameter = | S25: =(4*S24/PI())^0.5 -> #N/A | T25: ft
A26: Round to Standard Head Size = | B26: =EVEN(B25) -> #N/A | C26: ft | M26: =M25*12 -> #N/A | N26: inches | S26: =S25*12 -> #N/A | T26: inches
B27: =B26*12 -> #N/A | C27: inches | L27: Nozzle ID = | M27: =EVEN(M26) -> #N/A | N27: inches | R27: Nozzle ID = | S27: =EVEN(S26) -> #N/A | T27: inches
A28: Rounded Vessel ID, Dv = | B28: =IF(B27<36,36,B27) -> #N/A | C28: inches | D28: Minimum vessel ID = 3 ft
K29: Manway | Q29: Instrument Taps
A30: Determining Vessel Height (based on experience rules of thumb and allowances) | L30: Number of MWs = | M30: 2 | R30: Number of Taps = | S30: 4
A31: Liquid Retention Time, t = | B31: 1 | C31: minutes | D31: Depends on system/process. Note: API 12J recommends 1 minute for gas/oil separation. | L31: MW ID = | M31: 18 | N31: inches | R31: Tap ID = | S31: 2 | T31: inches
A32: Height required for t = | B32: =4/PI()*(B31*60*B10)/(B28/12)^2 -> #N/A | C32: ft
B33: =ROUNDUP(B32*12,0) -> #N/A | C33: inches | R33: Number of Taps = | S33: 2
A34: Estimated Mist Eliminator Height = | B34: 6 | C34: inches | R34: Tap ID = | S34: 1 | T34: inches
A35: Height allowance from Top TL to ME top = | B35: 12 | C35: inches | D35: TL = tangent line
A36: Height allowance from ME btm to inlet Nozzle = | B36: =IF(((B28+6))>42,(B28+6),42) -> #N/A | C36: inches | D36: D+6" or 42" minimum | K36: Feed
A37: Height allowance from Inlet Nozzle to HHLL = | B37: 24 | C37: inches | D37: 2 ft minimum; HHLL = High high liquid level | L37: Total Mass Flow Rate = | M37: =IF(Input!C42="Input",Input!C47,0)+IF(Input!E42="Input",Input!E47,0)+IF(Input!G42="Input",Input!G47,0) -> 0 | N37: lb/hr
A38: Est. height between HHLL and LLL = | B38: =IF(B33>12,B33,12) -> #N/A | C38: inches | D38: Minimum 1 ft for stable process control | L38: Average Mixture Density = | M38: =IF(Input!C42="Input",(((Input!C48*Input!C43+Input!C51*(1-Input!C43))*Input!C47/'Custom Rules'!M37)),0)+IF(Input!E42="Input",(((Input!E48*Input!E43+Input!E51*(1-Input!E43))*Input!E47/'Custom Rules'!M37)),0)+IF(Input!G42="Input",(((Input!G48*Input!G43+Input!G51*(1-Input!G43))*Input!G47/'Custom Rules'!M37)),0) -> 0 | N38: lb/ft3
A39: Height allowance between LLLL and bottom TL = | B39: 6 | C39: inches | L39: Max. Allow. Velocity = | M39: =50/(M38)^0.5 -> #DIV/0! | N39: ft/s
A40: T/T Length = | B40: =SUM(B33:B39) -> #N/A | C40: inches | L40: Min. cross-sect Area = | M40: =M37/M38/3600 -> #DIV/0! | N40: ft2
B41: =B40/12 -> #N/A | C41: feet | L41: Diameter = | M41: =IF(((4*M40/PI())^0.5)>4,(((4*M40)/(2*PI()))^0.5),((4*M40/PI())^0.5)) -> #DIV/0! | N41: ft | O41: Note: Maximum nozzle diameter is 48 inches
A42: Rounded Vessel T/T Height, L = | B42: =ROUNDUP(B41,0) -> #N/A | C42: feet | M42: =M41*12 -> #DIV/0! | N42: inches
A43: L/D Check = | B43: =B42*12/B28 -> #N/A | C43: Typically < 4 (if liquid/gas ratio is high and/or residence time is dominant, consider horizontal vessel design.) | L43: Nozzle ID = | M43: =EVEN(M42) -> #DIV/0! | N43: inches
L44: Number of Nozzles = | M44: =IF(((4*M40/PI())^0.5)>4,2,1) -> #DIV/0!
...

Sheet Output
B2: User Model Output Template
B3: SEPARATOR
B4: Item Information | C4: Value | D4: Units
B5: Equipment Name | C5: =Diagram!J7 | D5: =Diagram!K7
B6: CpDesignTemperature | C6: =ROUNDUP('Custom Rules'!B6+50,1) -> #NUM! | D6: ='Custom Rules'!C6 -> Deg F
B7: CpDesignGaugePressure | C7: =IF(ROUNDUP('Custom Rules'!B7*1.15,1)<50,50,ROUNDUP('Custom Rules'!B7*1.15,-1)) -> #NUM! | D7: =Input!D46 -> PSIG
B8: CpLiquidVolume | C8: =PI()*(C9/2)^2*C10*7.481 -> #N/A | D8: GALLONS
B9: CpVesselDiameter | C9: ='Custom Rules'!B28/12 -> #N/A | D9: FEET
B10: CpTangentTangentHeight | C10: ='Custom Rules'!B42 -> #N/A | D10: FEET
B11: CpNumberManholes | C11: ='Custom Rules'!M30 -> 2
B12: CpManholeDiameter | C12: ='Custom Rules'!M31 -> 18 | D12: INCHES
B13: CpNozzleALocation | C13: S
B14: CpNozzleAQuantity | C14: ='Custom Rules'!M44 -> #DIV/0!
B15: CpNozzleADiameter | C15: ='Custom Rules'!M43 -> #DIV/0! | D15: INCHES
B16: CpNozzleBLocation | C16: S
B17: CpNozzleBQuantity | C17: 1
B18: CpNozzleBDiameter | C18: ='Custom Rules'!M27 -> #N/A | D18: INCHES
B19: CpNozzleCLocation | C19: S
B20: CpNozzleCQuantity | C20: 1
B21: CpNozzleCDiameter | C21: ='Custom Rules'!S27 -> #N/A | D21: INCHES
B22: CpNozzleDLocation | C22: S
B23: CpNozzleDQuantity | C23: ='Custom Rules'!S30 -> 4
B24: CpNozzleDDiameter | C24: ='Custom Rules'!S31 -> 2 | D24: INCHES
B25: CpNozzleELocation | C25: S
B26: CpNozzleEQuantity | C26: ='Custom Rules'!S33 -> 2
B27: CpNozzleEDiameter | C27: ='Custom Rules'!S34 -> 1 | D27: INCHES
B49: Connection Stream Information | C49: Value | D49: Units | E49: Value | F49: Units | G49: Value | H49: Units | I49: Value | J49: Units | K49: Value | L49: Units
B50: Stream Name | C50: =IF(Input!C41="","",Input!C41) | D50: =IF(Input!D41="","",Input!D41) | E50: =IF(Input!E41="","",Input!E41) | F50: =IF(Input!F41="","",Input!F41) | G50: =IF(Input!G41="","",Input!G41) | H50: =IF(Input!H41="","",Input!H41) | I50: =IF(Input!K41="","",Input!K41) | J50: =IF(Input!L41="","",Input!L41) | K50: =IF(Input!M41="","",Input!M41) | L50: =IF(Input!N41="","",Input!N41)
B51: Stream Direction | C51: =IF(Input!C42="","",Input!C42) | D51: =IF(Input!D42="","",Input!D42) | E51: =IF(Input!E42="","",Input!E42) | F51: =IF(Input!F42="","",Input!F42) | G51: =IF(Input!G42="","",Input!G42) | H51: =IF(Input!H42="","",Input!H42) | I51: =IF(Input!K42="","",Input!K42) | J51: =IF(Input!L42="","",Input!L42) | K51: =IF(Input!M42="","",Input!M42) | L51: =IF(Input!N42="","",Input!N42)
B52: Temperature | C52: =IF(Input!C45="","",Input!C45) | D52: =IF(Input!D45="","",Input!D45) -> F | E52: =IF(Input!E45="","",Input!E45) | F52: =IF(Input!F45="","",Input!F45) | G52: =IF(Input!G45="","",Input!G45) | H52: =IF(Input!H45="","",Input!H45) | I52: =IF(Input!I45="","",Input!I45) | J52: =IF(Input!J45="","",Input!J45) | ... L52: =IF(Input!L45="","",Input!L45)
B53: Pressure | C53: =IF(Input!C46="","",Input!C46) | D53: =IF(Input!D46="","",Input!D46) -> PSIG | E53: =IF(Input!E46="","",Input!E46) | F53: =IF(Input!F46="","",Input!F46) | G53: =IF(Input!G46="","",Input!G46) | H53: =IF(Input!H46="","",Input!H46) | I53: =IF(Input!I46="","",Input!I46) | J53: =IF(Input!J46="","",Input!J46) | ... L53: =IF(Input!L46="","",Input!L46)
B54: Total Mass Flow | C54: =IF(Input!C47="","",Input!C47) | D54: =IF(Input!D47="","",Input!D47) -> LB/H | E54: =IF(Input!E47="","",Input!E47) | F54: =IF(Input!F47="","",Input!F47) | G54: =IF(Input!G47="","",Input!G47) | H54: =IF(Input!H47="","",Input!H47) | I54: =IF(Input!I47="","",Input!I47) | J54: =IF(Input!J47="","",Input!J47) | ... L54: =IF(Input!L47="","",Input!L47)
B55: Total Mass Density | C55: =IF(Input!#REF!="","",Input!#REF!) -> #REF! | D55: =IF(Input!#REF!="","",Input!#REF!) -> #REF! | E55: =IF(Input!#REF!="","",Input!#REF!) -> #REF! | F55: =IF(Input!#REF!="","",Input!#REF!) -> #REF! | G55: =IF(Input!#REF!="","",Input!#REF!) -> #REF! | H55: =IF(Input!#REF!="","",Input!#REF!) -> #REF! | I55: =IF(Input!#REF!="","",Input!#REF!) -> #REF! | J55: =IF(Input!#REF!="","",Input!#REF!) -> #REF! | ... L55: =IF(Input!#REF!="","",Input!#REF!) -> #REF!
B56: Molecular Weight | C56: =IF(Input!C44="","",Input!C44) | D56: =IF(Input!D44="","",Input!D44) | E56: =IF(Input!E44="","",Input!E44) | F56: =IF(Input!F44="","",Input!F44) | G56: =IF(Input!G44="","",Input!G44) | H56: =IF(Input!H44="","",Input!H44) | I56: =IF(Input!I44="","",Input!I44) | J56: =IF(Input!J44="","",Input!J44) | ... L56: =IF(Input!L44="","",Input!L44)
B57: Vapor Conductivity | C57: =IF(Input!C43="","",Input!C43) | D57: =IF(Input!D43="","",Input!D43) | E57: =IF(Input!E43="","",Input!E43) | F57: =IF(Input!F43="","",Input!F43) | G57: =IF(Input!G43="","",Input!G43) | H57: =IF(Input!H43="","",Input!H43) | I57: =IF(Input!I43="","",Input!I43) | J57: =IF(Input!J43="","",Input!J43) | ... L57: =IF(Input!L43="","",Input!L43)
B58: Vapor Mass Density | C58: =IF(Input!C48="","",Input!C48) | D58: =IF(Input!D48="","",Input!D48) -> PCF | E58: =IF(Input!E48="","",Input!E48) | F58: =IF(Input!F48="","",Input!F48) | G58: =IF(Input!G48="","",Input!G48) | H58: =IF(Input!H48="","",Input!H48) | I58: =IF(Input!I48="","",Input!I48) | J58: =IF(Input!J48="","",Input!J48) | ... L58: =IF(Input!L48="","",Input!L48)
B59: Vapor Mass Flow | C59: =IF(Input!C49="","",Input!C49) | D59: =IF(Input!D49="","",Input!D49) -> LB/H | E59: =IF(Input!E49="","",Input!E49) | F59: =IF(Input!F49="","",Input!F49) | G59: =IF(Input!G49="","",Input!G49) | H59: =IF(Input!H49="","",Input!H49) | I59: =IF(Input!I49="","",Input!I49) | J59: =IF(Input!J49="","",Input!J49) | ... L59: =IF(Input!L49="","",Input!L49)
B60: Vapor Specific Heat Capacity | C60: =IF(Input!C50="","",Input!C50) | D60: =IF(Input!D50="","",Input!D50) -> CFH | E60: =IF(Input!E50="","",Input!E50) | F60: =IF(Input!F50="","",Input!F50) | G60: =IF(Input!G50="","",Input!G50) | H60: =IF(Input!H50="","",Input!H50) | I60: =IF(Input!I50="","",Input!I50) | J60: =IF(Input!J50="","",Input!J50) | ... L60: =IF(Input!L50="","",Input!L50)
B61: Vapor Viscosity | C61: =IF(Input!#REF!="","",Input!#REF!) -> #REF! | D61: =IF(Input!#REF!="","",Input!#REF!) -> #REF! | E61: =IF(Input!#REF!="","",Input!#REF!) -> #REF! | F61: =IF(Input!#REF!="","",Input!#REF!) -> #REF! | G61: =IF(Input!#REF!="","",Input!#REF!) -> #REF! | H61: =IF(Input!#REF!="","",Input!#REF!) -> #REF! | I61: =IF(Input!#REF!="","",Input!#REF!) -> #REF! | J61: =IF(Input!#REF!="","",Input!#REF!) -> #REF! | ... L61: =IF(Input!#REF!="","",Input!#REF!) -> #REF!
B62: Liquid Conductivity | C62: =IF(Input!#REF!="","",Input!#REF!) -> #REF! | D62: =IF(Input!#REF!="","",Input!#REF!) -> #REF! | E62: =IF(Input!#REF!="","",Input!#REF!) -> #REF! | F62: =IF(Input!#REF!="","",Input!#REF!) -> #REF! | G62: =IF(Input!#REF!="","",Input!#REF!) -> #REF! | H62: =IF(Input!#REF!="","",Input!#REF!) -> #REF! | I62: =IF(Input!#REF!="","",Input!#REF!) -> #REF! | J62: =IF(Input!#REF!="","",Input!#REF!) -> #REF! | ... L62: =IF(Input!#REF!="","",Input!#REF!) -> #REF!
...
