Workbook
Name __TBL_0_ConstructionIndirects__X: 'Project Indirect Metrics'!$A$3
Name _TBL_0_ProjectInfo_FIXED: 'Project Information'!$B$3
Name ASCEOccupancyRiskCategory: 'Project Information'!$B$23
Name BaseUOM: 'Project Information'!$B$10
Name CivilDesignCode: 'Project Information'!$B$22
Name ConstructionType: 'Project Information'!$B$8
Name CostBasis: 'Project Information'!$B$15
Name CountryBase: 'Project Information'!$B$9
Name CurrencyName: 'Project Information'!$B$11
Name CurrencySymbol: 'Project Information'!$B$12
Name ElectricalClassDivZone: 'Project Information'!$B$29
Name ElectricalDistributionSys: 'Project Information'!$B$31
Name EstimateClass: 'Project Information'!$B$13
Name EstimateOrActuals: 'Project Information'!$B$5
Name InstrumentationSystem: 'Project Information'!$B$28
Name ListBaseUoM: DropdownLists!$B$1:$B$2
Name ListCivilDesignCode: DropdownLists!$F$1:$F$2
Name ListConstructionType: DropdownLists!$C$20:$C$22
Name ListCountryBase: DropdownLists!$A$1:$A$5
Name ListElectricalClassDivZone: DropdownLists!$L$1:$L$9
Name ListElectricalDistributionSys: DropdownLists!$N$1:$N$2
Name ListEstimateOrActuals: DropdownLists!$A$20:$A$21
Name ListInstrumentationSystem: DropdownLists!$K$1:$K$2
Name ListOccupancyRiskCategory: DropdownLists!$G$1:$G$4
Name ListPIDDesignLevel: DropdownLists!$J$1:$J$3
Name ListPipeFlangeRatingStd: DropdownLists!$E$1:$E$4
Name ListPipeWallThkStd: DropdownLists!$D$1:$D$4
Name ListPowerSupplyFreq: DropdownLists!$M$1:$M$2
Name ListProcessDescription: DropdownLists!$D$20:$D$24
Name ListProjectType: DropdownLists!$B$20:$B$22
Name ListSoilType: DropdownLists!$I$1:$I$11
Name ListUBCZone: DropdownLists!$H$1:$H$6
Name ListUOMArea: DropdownLists!$H$20:$H$21
Name ListUOMEquipQty: DropdownLists!$E$20:$E$21
Name ListUOMFireproofing: DropdownLists!$K$20:$K$23
Name ListUOMLength: DropdownLists!$F$20:$F$21
Name ListUOMPaving: DropdownLists!$L$20:$L$23
Name ListUOMPipeInsulation: DropdownLists!$J$20:$J$23
Name ListUOMSteelQty: DropdownLists!$G$20:$G$21
Name ListUOMVolume: DropdownLists!$I$20:$I$21
Name ListVesselDesignCode: DropdownLists!$C$1:$C$6
Name PIDDesignLevel: 'Project Information'!$B$27
Name PipeFlangeRatingStd: 'Project Information'!$B$20
Name PipeWallThicknessStd: 'Project Information'!$B$21
Name PowerSupplyFreq: 'Project Information'!$B$30
Name PreparedBy: 'Project Information'!$B$14
Name ProcessDescription: 'Project Information'!$B$7
Name ProjectLocation: 'Project Information'!$B$4
Name ProjectTitle: 'Project Information'!$B$3
Name ProjectType: 'Project Information'!$B$6
Name SeismicHorizontalAcceleration: 'Project Information'!$B$24
Name SoilType: 'Project Information'!$B$26
Name UBCZone: 'Project Information'!$B$25
Name UOMCivilEarthworkQty: 'Project Direct Metrics'!$D$61
Name UOMCivilPavingQty: 'Project Direct Metrics'!$D$64
Name UOMCivilRoadRRQty: 'Project Direct Metrics'!$D$62
Name UOMConcreteGroutQty: 'Project Direct Metrics'!$D$65
Name UOMElectricalWireLength: 'Project Direct Metrics'!$D$98
Name UOMEquipFireproofingQty: 'Project Direct Metrics'!$D$121
Name UOMEquipInsulationQty: 'Project Direct Metrics'!$D$119

Sheet WorkflowUpload_DO_NOT_EDIT
A1: Project Title | B1: Project Location | C1: Estimate Or Actuals | D1: Project Type | E1: Process Description | F1: Construction Type | G1: Country Base | H1: Base Units of Measure | I1: Currency Name | J1: Currency Symbol | K1: Estimate Class | L1: Prepared By | M1: Cost Basis Year | N1: Vessel design code | O1: Pipe flange rating standard | P1: Pipe wall thickness standard | Q1: Civil/structural design loads reference code | R1: ASCE 7 occupancy / risk category | S1: Seismic horizontal acceleration (g) | T1: UBC zone | U1: Soil type | V1: Piping and instrumentation design | W1: Instrumentation system | X1: Electrical class and division or zone | Y1: Power supply frequency | Z1: Electrical distribution system | AA1: ISBL: Boiler Plant Equipment Qty | AB1: ISBL: Centrifugal Compressors Qty | AC1: ISBL: Crushers, Mills Qty | AD1: ISBL: Drivers Qty | AE1: ISBL: Fans, Blowers Qty | AF1: ISBL: Flares Qty | AG1: ISBL: Fluid Separation Equipment Qty | AH1: ISBL: Furnaces, Heaters Qty | AI1: ISBL: Generators Qty | AJ1: ISBL: Heat Exchangers Qty | AK1: ISBL: Material Handling Equipment Qty | AL1: ISBL: Package Units Qty | AM1: ISBL: Process Vessels Qty | AN1: ISBL: Pumps Qty | AO1: ISBL: Reactors, Mixers Qty | AP1: ISBL: Reciprocating Compressors Qty | AQ1: ISBL: Solids Separation Equipment Qty | AR1: ISBL: Storage Vessels Qty | AS1: ISBL: Turbo Expanders Qty | AT1: ISBL: Other Equipment Items Qty | AU1: ISBL: Equipment Demolition Qty | AV1: OSBL: Boiler Plant Equipment Qty | AW1: OSBL: Centrifugal Compressors Qty | AX1: OSBL: Crushers, Mills Qty | AY1: OSBL: Drivers Qty | AZ1: OSBL: Fans, Blowers Qty | BA1: OSBL: Flares Qty | BB1: OSBL: Fluid Separation Equipment Qty | BC1: OSBL: Furnaces, Heaters Qty | BD1: OSBL: Generators Qty | BE1: OSBL: Heat Exchangers Qty | BF1: OSBL: Material Handling Equipment Qty | BG1: OSBL: Package Units Qty | BH1: OSBL: Process Vessels Qty | BI1: OSBL: Pumps Qty | BJ1: OSBL: Reactors, Mixers Qty | BK1: OSBL: Reciprocating Compressors Qty | BL1: OSBL: Solids Separation Equipment Qty | BM1: OSBL: Storage Vessels Qty | BN1: OSBL: Turbo Expanders Qty | BO1: OSBL: Other Equipment Items Qty | BP1: OSBL: Equipment Demolition Qty | BQ1: ISBL: CS Pipe Qty | BR1: ISBL: CS Valves, Fittings Qty | BS1: ISBL: SS Pipe Qty | BT1: ISBL: SS Valves, Fittings Qty | BU1: ISBL: Non-ferrous Pipe Qty | BV1: ISBL: Non-ferrous Valves, Fittings Qty | BW1: ISBL: Lined Pipe Qty | BX1: ISBL: Lined Valves, Fittings Qty | BY1: ISBL: Non-metallic Pipe Qty | BZ1: ISBL: Non-metallic Valves, Fittings Qty | CA1: ISBL: Specialty Piping Items Qty | CB1: ISBL: Firewater Piping Qty | CC1: ISBL: Ductwork, Launders Qty | CD1: ISBL: Pipelines Qty | CE1: ISBL: Other Piping Qty | CF1: ISBL: Pipe Demolition Qty | CG1: OSBL: CS Pipe Qty | CH1: OSBL: CS Valves, Fittings Qty | CI1: OSBL: SS Pipe Qty | CJ1: OSBL: SS Valves, Fittings Qty | CK1: OSBL: Non-ferrous Pipe Qty | CL1: OSBL: Non-ferrous Valves, Fittings Qty | CM1: OSBL: Lined Pipe Qty | CN1: OSBL: Lined Valves, Fittings Qty | CO1: OSBL: Non-metallic Pipe Qty | CP1: OSBL: Non-metallic Valves, Fittings Qty | CQ1: OSBL: Specialty Piping Items Qty | CR1: OSBL: Firewater Piping Qty | CS1: OSBL: Ductwork, Launders Qty | CT1: OSBL: Pipelines Qty | CU1: OSBL: Other Piping Qty | CV1: OSBL: Pipe Demolition Qty | CW1: ISBL: Above Ground (AG) Piping Qty | CX1: ISBL: Underground (UG) Piping Qty | CY1: ISBL: Extra-small Diameter Qty | CZ1: ISBL: Small Diameter Qty | DA1: ISBL: Medium Diameter Qty | DB1: ISBL: Large Diameter Qty | DC1: ISBL: Extra-large Diameter Qty | DD1: OSBL: Above Ground (AG) Piping Qty | DE1: OSBL: Underground (UG) Piping Qty | DF1: OSBL: Extra-small Diameter Qty | DG1: OSBL: Small Diameter Qty | DH1: OSBL: Medium Diameter Qty | DI1: OSBL: Large Diameter Qty | DJ1: OSBL: Extra-large Diameter Qty | DK1: ISBL: Earthwork Qty | DL1: ISBL: Roads, Railroads Qty | DM1: ISBL: Piling Qty | DN1: ISBL: Paving Qty | DO1: ISBL: Concrete Qty | DP1: ISBL: Grout Qty | DQ1: ISBL: Rebar Qty | DR1: ISBL: Buildings, Architectural Qty | DS1: OSBL: Earthwork Qty | DT1: OSBL: Roads, Railroads Qty | DU1: OSBL: Piling Qty | DV1: OSBL: Paving Qty | DW1: OSBL: Concrete Qty | DX1: OSBL: Grout Qty | DY1: OSBL: Rebar Qty | DZ1: OSBL: Buildings, Architectural Qty | EA1: ISBL: Extra Light Qty | EB1: ISBL: Light Qty | EC1: ISBL: Medium Qty | ED1: ISBL: Heavy Qty | EE1: ISBL: Extra Heavy Qty | EF1: ISBL: Offshore Steel Qty | EG1: ISBL: Other Steel Items Qty | EH1: ISBL: Steel Demolition Qty | EI1: OSBL: Extra Light Qty | EJ1: OSBL: Light Qty | EK1: OSBL: Medium Qty | EL1: OSBL: Heavy Qty | EM1: OSBL: Extra Heavy Qty | EN1: OSBL: Offshore Steel Qty | EO1: OSBL: Other Steel Items Qty | EP1: OSBL: Steel Demolition Qty | EQ1: ISBL: Sensors Qty | ER1: ISBL: Control Valves Qty | ES1: ISBL: Wiring, Cable, Data Highway, Fiber Optic Qty | ET1: ISBL: Junction Boxes, Cabinets Etc. Qty | EU1: ISBL: Instrumentation Conduit, Fittings Qty | EV1: ISBL: Instrumentation Cable Tray, Supports Qty | EW1: OSBL: Sensors Qty | EX1: OSBL: Control Valves Qty | EY1: OSBL: Wiring, Cable, Data Highway, Fiber Optic Qty | EZ1: OSBL: Junction Boxes, Cabinets Etc. Qty | FA1: OSBL: Instrumentation Conduit, Fittings Qty | FB1: OSBL: Instrumentation Cable Tray, Supports Qty | FC1: ISBL: High Voltage Electrical Cable Qty | FD1: ISBL: Medium Voltage Electrical Cable Qty | FE1: ISBL: Low Voltage Electrical Cable Qty | FF1: ISBL: Control Cable Qty | FG1: ISBL: Lighting Cable Qty | FH1: ISBL: Conduit, Fittings Qty | FI1: ISBL: Cable Tray, Supports Qty | FJ1: ISBL: Transformers, Switchgear Qty | FK1: ISBL: Motor Control Center Qty | FL1: ISBL: Other Electrical Equipment Qty | FM1: ISBL: Other Electrical Items Qty | FN1: ISBL: Above Ground Electrical Qty | FO1: ISBL: Below Ground Electrical Qty | FP1: OSBL: High Voltage Electrical Cable Qty | FQ1: OSBL: Medium Voltage Electrical Cable Qty | FR1: OSBL: Low Voltage Electrical Cable Qty | FS1: OSBL: Control Cable Qty | FT1: OSBL: Lighting Cable Qty | FU1: OSBL: Conduit, Fittings Qty | FV1: OSBL: Cable Tray, Supports Qty | FW1: OSBL: Transformers, Switchgear Qty | FX1: OSBL: Motor Control Center Qty | FY1: OSBL: Other Electrical Equipment Qty | FZ1: OSBL: Other Electrical Items Qty | GA1: OSBL: Above Ground Electrical Qty | GB1: OSBL: Below Ground Electrical Qty | GC1: ISBL: Equipment Insulation Qty | GD1: ISBL: Pipe Insulation Qty | GE1: ISBL: Equipment Fireproofing Qty | GF1: ISBL: Steel Fireproofing Qty | GG1: OSBL: Equipment Insulation Qty | GH1: OSBL: Pipe Insulation Qty | GI1: OSBL: Equipment Fireproofing Qty | GJ1: OSBL: Steel Fireproofing Qty | GK1: ISBL: Equipment Paint Qty | GL1: ISBL: Pipe Paint Qty | GM1: ISBL: Steel Paint Qty | GN1: ISBL: Surface Preparation Qty | GO1: ISBL: Module Paint Qty | GP1: ISBL: Other Paint Qty | GQ1: ISBL: Paint Demolition Qty | GR1: OSBL: Equipment Paint Qty | GS1: OSBL: Pipe Paint Qty | GT1: OSBL: Steel Paint Qty | GU1: OSBL: Surface Preparation Qty | GV1: OSBL: Module Paint Qty | GW1: OSBL: Other Paint Qty | GX1: OSBL: Paint Demolition Qty | GY1: ISBL: Boiler Plant Equip. Matl. Cost | GZ1: ISBL: Centrifugal Compressors Matl. Cost | HA1: ISBL: Crushers, Mills Matl. Cost | HB1: ISBL: Drivers Matl. Cost | HC1: ISBL: Fans, Blowers Matl. Cost | HD1: ISBL: Flares Matl. Cost | HE1: ISBL: Fluid Separation Equip. Matl. Cost | HF1: ISBL: Furnaces, Heaters Matl. Cost | HG1: ISBL: Generators Matl. Cost | HH1: ISBL: Heat Exchangers Matl. Cost | HI1: ISBL: Material Handling Equip. Matl. Cost | HJ1: ISBL: Package Units Matl. Cost | HK1: ISBL: Process Vessels Matl. Cost | HL1: ISBL: Pumps Matl. Cost | HM1: ISBL: Reactors, Mixers Matl. Cost | HN1: ISBL: Reciprocating Compressors Matl. Cost | HO1: ISBL: Solids Separation Equip. Matl. Cost | HP1: ISBL: Storage Vessels Matl. Cost | HQ1: ISBL: Turbo Expanders Matl. Cost | HR1: ISBL: Other Equipment Items Matl. Cost | HS1: ISBL: Design Allowance Matl. Cost | HT1: ISBL: Warehouse Spares Matl. Cost | HU1: ISBL: Equipment Demolition Matl. Cost | HV1: OSBL: Boiler Plant Equip. Matl. Cost | HW1: OSBL: Centrifugal Compressors Matl. Cost | HX1: OSBL: Crushers, Mills Matl. Cost | HY1: OSBL: Drivers Matl. Cost | HZ1: OSBL: Fans, Blowers Matl. Cost | IA1: OSBL: Flares Matl. Cost | IB1: OSBL: Fluid Separation Equip. Matl. Cost | IC1: OSBL: Furnaces, Heaters Matl. Cost | ID1: OSBL: Generators Matl. Cost | IE1: OSBL: Heat Exchangers Matl. Cost | IF1: OSBL: Material Handling Equip. Matl. Cost | IG1: OSBL: Package Units Matl. Cost | IH1: OSBL: Process Vessels Matl. Cost | II1: OSBL: Pumps Matl. Cost | IJ1: OSBL: Reactors, Mixers Matl. Cost | IK1: OSBL: Reciprocating Compressors Matl. Cost | IL1: OSBL: Solids Separation Equip. Matl. Cost | IM1: OSBL: Storage Vessels Matl. Cost | IN1: OSBL: Turbo Expanders Matl. Cost | IO1: OSBL: Other Equipment Items Matl. Cost | IP1: OSBL: Design Allowance Matl. Cost | IQ1: OSBL: Warehouse Spares Matl. Cost | IR1: OSBL: Equipment Demolition Matl. Cost | IS1: ISBL: CS Pipe Matl. Cost | IT1: ISBL: CS Valves, Fittings Matl. Cost | IU1: ISBL: SS Pipe Matl. Cost | IV1: ISBL: SS Valves, Fittings Matl. Cost | IW1: ISBL: Non-ferrous Pipe Matl. Cost | IX1: ISBL: Non-ferrous Valves, Fittings Matl. Cost | IY1: ISBL: Lined Pipe Matl. Cost | IZ1: ISBL: Lined Valves, Fittings Matl. Cost | JA1: ISBL: Non-metallic Pipe Matl. Cost | JB1: ISBL: Non-metallic Valves, Fittings Matl. Cost | JC1: ISBL: Specialty Piping Items Matl. Cost | JD1: ISBL: Firewater Piping Matl. Cost | JE1: ISBL: Ductwork, Launders Matl. Cost | JF1: ISBL: Pipelines Matl. Cost | JG1: ISBL: Other Piping Matl. Cost | JH1: ISBL: Pipe Testing Matl. Cost | JI1: ISBL: Pipe Demolition Matl. Cost | JJ1: ISBL: Above Ground (AG) Piping Matl. Cost | JK1: ISBL: Underground (UG) Piping Matl. Cost | JL1: ISBL: Extra-small Diameter Matl. Cost | JM1: ISBL: Small Diameter Matl. Cost | JN1: ISBL: Medium Diameter Matl. Cost | JO1: ISBL: Large Diameter Matl. Cost | JP1: ISBL: Extra-large Diameter Matl. Cost | JQ1: OSBL: CS Pipe Matl. Cost | JR1: OSBL: CS Valves, Fittings Matl. Cost | JS1: OSBL: SS Pipe Matl. Cost | JT1: OSBL: SS Valves, Fittings Matl. Cost | JU1: OSBL: Non-ferrous Pipe Matl. Cost | JV1: OSBL: Non-ferrous Valves, Fittings Matl. Cost | JW1: OSBL: Lined Pipe Matl. Cost | JX1: OSBL: Lined Valves, Fittings Matl. Cost | JY1: OSBL: Non-metallic Pipe Matl. Cost | JZ1: OSBL: Non-metallic Valves, Fittings Matl. Cost | KA1: OSBL: Specialty Piping Items Matl. Cost | KB1: OSBL: Firewater Piping Matl. Cost | KC1: OSBL: Ductwork, Launders Matl. Cost | KD1: OSBL: Pipelines Matl. Cost | KE1: OSBL: Other Piping Matl. Cost | KF1: OSBL: Pipe Testing Matl. Cost | KG1: OSBL: Pipe Demolition Matl. Cost | KH1: OSBL: Above Ground (AG) Piping Matl. Cost | KI1: OSBL: Underground (UG) Piping Matl. Cost | KJ1: OSBL: Extra-small Diameter Matl. Cost | KK1: OSBL: Small Diameter Matl. Cost | KL1: OSBL: Medium Diameter Matl. Cost | KM1: OSBL: Large Diameter Matl. Cost | KN1: OSBL: Extra-large Diameter Matl. Cost | KO1: ISBL: Earthwork Matl. Cost | KP1: ISBL: Roads, Railroads Matl. Cost | KQ1: ISBL: Piling Matl. Cost | KR1: ISBL: Paving Matl. Cost | KS1: ISBL: Concrete Matl. Cost | KT1: ISBL: Grout Matl. Cost | KU1: ISBL: Rebar Matl. Cost | KV1: ISBL: Buildings, Architectural Matl. Cost | KW1: ISBL: Other Sitework Matl. Cost | KX1: ISBL: Other Civil Matl. Cost | KY1: ISBL: Civil Demolition Matl. Cost | KZ1: OSBL: Earthwork Matl. Cost | LA1: OSBL: Roads, Railroads Matl. Cost | LB1: OSBL: Piling Matl. Cost | LC1: OSBL: Paving Matl. Cost | LD1: OSBL: Concrete Matl. Cost | LE1: OSBL: Grout Matl. Cost | LF1: OSBL: Rebar Matl. Cost | LG1: OSBL: Buildings, Architectural Matl. Cost | LH1: OSBL: Other Sitework Matl. Cost | LI1: OSBL: Other Civil Matl. Cost | LJ1: OSBL: Civil Demolition Matl. Cost | LK1: ISBL: Extra Light Steel Matl. Cost | LL1: ISBL: Light Steel Matl. Cost | LM1: ISBL: Medium Steel Matl. Cost | LN1: ISBL: Heavy Steel Matl. Cost | LO1: ISBL: Extra Heavy Steel Matl. Cost | LP1: ISBL: Offshore Steel Matl. Cost | LQ1: ISBL: Other Steel Items Matl. Cost | LR1: ISBL: Steel Demolition Matl. Cost | LS1: OSBL: Extra Light Steel Matl. Cost | LT1: OSBL: Light Steel Matl. Cost | LU1: OSBL: Medium Steel Matl. Cost | LV1: OSBL: Heavy Steel Matl. Cost | LW1: OSBL: Extra Heavy Steel Matl. Cost | LX1: OSBL: Offshore Steel Matl. Cost | LY1: OSBL: Other Steel Items Matl. Cost | LZ1: OSBL: Steel Demolition Matl. Cost | MA1: ISBL: Sensors Matl. Cost | MB1: ISBL: Control Valves Matl. Cost | MC1: ISBL: Wiring, Cable, Data Highway, Fiber Optic Matl. Cost | MD1: ISBL: Junction Boxes, Cabinets Etc. Matl. Cost | ME1: ISBL: Instru. Conduit, Fittings Matl. Cost | MF1: ISBL: Instru. Cable Tray, Supports Matl. Cost | MG1: ISBL: Computer Control Matl. Cost | MH1: ISBL: Instrument Testing Matl. Cost | MI1: ISBL: Other Instrumentation Items Matl. Cost | MJ1: ISBL: Instrumentation Demolition Matl. Cost | MK1: OSBL: Sensors Matl. Cost | ML1: OSBL: Control Valves Matl. Cost | MM1: OSBL: Wiring, Cable, Data Highway, Fiber Optic Matl. Cost | MN1: OSBL: Junction Boxes, Cabinets Etc. Matl. Cost | MO1: OSBL: Instru. Conduit, Fittings Matl. Cost | MP1: OSBL: Instru. Cable Tray, Supports Matl. Cost | MQ1: OSBL: Computer Control Matl. Cost | MR1: OSBL: Instrument Testing Matl. Cost | MS1: OSBL: Other Instrumentation Items Matl. Cost | MT1: OSBL: Instrumentation Demolition Matl. Cost | MU1: ISBL: HV Electrical Cable Matl. Cost | MV1: ISBL: MV Electrical Cable Matl. Cost | MW1: ISBL: LV Electrical Cable Matl. Cost | MX1: ISBL: Control Cable Matl. Cost | MY1: ISBL: Lighting Cable Matl. Cost | MZ1: ISBL: Elec. Conduit, Fittings Matl. Cost | NA1: ISBL: Elec. Cable Tray, Supports Matl. Cost | NB1: ISBL: Transformers, Switchgear Matl. Cost | NC1: ISBL: Motor Control Center Matl. Cost | ND1: ISBL: Other Electrical Equip. Matl. Cost | NE1: ISBL: Other Electrical Items Matl. Cost | NF1: ISBL: Electrical Testing Matl. Cost | NG1: ISBL: Electrical Demolition Matl. Cost | NH1: ISBL: Above Ground Electrical Matl. Cost | NI1: ISBL: Below Ground Electrical Matl. Cost | NJ1: OSBL: HV Electrical Cable Matl. Cost | NK1: OSBL: MV Electrical Cable Matl. Cost | NL1: OSBL: LV Electrical Cable Matl. Cost | NM1: OSBL: Control Cable Matl. Cost | NN1: OSBL: Lighting Cable Matl. Cost | NO1: OSBL: Elec. Conduit, Fittings Matl. Cost | NP1: OSBL: Elec. Cable Tray, Supports Matl. Cost | NQ1: OSBL: Transformers, Switchgear Matl. Cost | NR1: OSBL: Motor Control Center Matl. Cost | NS1: OSBL: Other Electrical Equip. Matl. Cost | NT1: OSBL: Other Electrical Items Matl. Cost | NU1: OSBL: Electrical Testing Matl. Cost | NV1: OSBL: Electrical Demolition Matl. Cost | NW1: OSBL: Above Ground Electrical Matl. Cost | NX1: OSBL: Below Ground Electrical Matl. Cost | NY1: ISBL: Equipment Insulation Matl. Cost | NZ1: ISBL: Pipe Insulation Matl. Cost | OA1: ISBL: Equipment Fireproofing Matl. Cost | OB1: ISBL: Steel Fireproofing Matl. Cost | OC1: ISBL: Other Insulation, Fireproofing Matl. Cost | OD1: ISBL: Insulation, Fireproofing Demolition Matl. Cost | OE1: OSBL: Equipment Insulation Matl. Cost | OF1: OSBL: Pipe Insulation Matl. Cost | OG1: OSBL: Equipment Fireproofing Matl. Cost | OH1: OSBL: Steel Fireproofing Matl. Cost | OI1: OSBL: Other Insulation, Fireproofing Matl. Cost | OJ1: OSBL: Insulation, Fireproofing Demolition Matl. Cost | OK1: ISBL: Equipment Paint Matl. Cost | OL1: ISBL: Pipe Paint Matl. Cost | OM1: ISBL: Steel Paint Matl. Cost | ON1: ISBL: Surface Preparation Matl. Cost | OO1: ISBL: Module Paint Matl. Cost | OP1: ISBL: Other Paint Matl. Cost | OQ1: ISBL: Paint Demolition Matl. Cost | OR1: OSBL: Equipment Paint Matl. Cost | OS1: OSBL: Pipe Paint Matl. Cost | OT1: OSBL: Steel Paint Matl. Cost | OU1: OSBL: Surface Preparation Matl. Cost | OV1: OSBL: Module Paint Matl. Cost | OW1: OSBL: Other Paint Matl. Cost | OX1: OSBL: Paint Demolition Matl. Cost | OY1: ISBL: Boiler Plant Equip. MHrs | OZ1: ISBL: Centrifugal Compressors MHrs | PA1: ISBL: Crushers, Mills MHrs | PB1: ISBL: Drivers MHrs | PC1: ISBL: Fans, Blowers MHrs | PD1: ISBL: Flares MHrs | PE1: ISBL: Fluid Separation Equip. MHrs | PF1: ISBL: Furnaces, Heaters MHrs | PG1: ISBL: Generators MHrs | PH1: ISBL: Heat Exchangers MHrs | PI1: ISBL: Material Handling Equip. MHrs | PJ1: ISBL: Package Units MHrs | PK1: ISBL: Process Vessels MHrs | PL1: ISBL: Pumps MHrs | PM1: ISBL: Reactors, Mixers MHrs | PN1: ISBL: Reciprocating Compressors MHrs | PO1: ISBL: Solids Separation Equip. MHrs | PP1: ISBL: Storage Vessels MHrs | PQ1: ISBL: Turbo Expanders MHrs | PR1: ISBL: Other Equipment Items MHrs | PS1: ISBL: Design Allowance MHrs | PT1: ISBL: Warehouse Spares MHrs | PU1: ISBL: Equipment Demolition MHrs | PV1: OSBL: Boiler Plant Equip. MHrs | PW1: OSBL: Centrifugal Compressors MHrs | PX1: OSBL: Crushers, Mills MHrs | PY1: OSBL: Drivers MHrs | PZ1: OSBL: Fans, Blowers MHrs | QA1: OSBL: Flares MHrs | QB1: OSBL: Fluid Separation Equip. MHrs | QC1: OSBL: Furnaces, Heaters MHrs | QD1: OSBL: Generators MHrs | QE1: OSBL: Heat Exchangers MHrs | QF1: OSBL: Material Handling Equip. MHrs | QG1: OSBL: Package Units MHrs | QH1: OSBL: Process Vessels MHrs | QI1: OSBL: Pumps MHrs | QJ1: OSBL: Reactors, Mixers MHrs | QK1: OSBL: Reciprocating Compressors MHrs | QL1: OSBL: Solids Separation Equip. MHrs | QM1: OSBL: Storage Vessels MHrs | QN1: OSBL: Turbo Expanders MHrs | QO1: OSBL: Other Equipment Items MHrs | QP1: OSBL: Design Allowance MHrs | QQ1: OSBL: Warehouse Spares MHrs | QR1: OSBL: Equipment Demolition MHrs | QS1: ISBL: CS Pipe MHrs | QT1: ISBL: CS Valves, Fittings MHrs | QU1: ISBL: SS Pipe MHrs | QV1: ISBL: SS Valves, Fittings MHrs | QW1: ISBL: Non-ferrous Pipe MHrs | QX1: ISBL: Non-ferrous Valves, Fittings MHrs | QY1: ISBL: Lined Pipe MHrs | QZ1: ISBL: Lined Valves, Fittings MHrs | RA1: ISBL: Non-metallic Pipe MHrs | RB1: ISBL: Non-metallic Valves, Fittings MHrs | RC1: ISBL: Specialty Piping Items MHrs | RD1: ISBL: Firewater Piping MHrs | RE1: ISBL: Ductwork, Launders MHrs | RF1: ISBL: Pipelines MHrs | RG1: ISBL: Other Piping MHrs | RH1: ISBL: Pipe Testing MHrs | RI1: ISBL: Pipe Demolition MHrs | RJ1: ISBL: Above Ground (AG) Piping MHrs | RK1: ISBL: Underground (UG) Piping MHrs | RL1: ISBL: Extra-small Diameter MHrs | RM1: ISBL: Small Diameter MHrs | RN1: ISBL: Medium Diameter MHrs | RO1: ISBL: Large Diameter MHrs | RP1: ISBL: Extra-large Diameter MHrs | RQ1: OSBL: CS Pipe MHrs | RR1: OSBL: CS Valves, Fittings MHrs | RS1: OSBL: SS Pipe MHrs | RT1: OSBL: SS Valves, Fittings MHrs | RU1: OSBL: Non-ferrous Pipe MHrs | RV1: OSBL: Non-ferrous Valves, Fittings MHrs | RW1: OSBL: Lined Pipe MHrs | RX1: OSBL: Lined Valves, Fittings MHrs | RY1: OSBL: Non-metallic Pipe MHrs | RZ1: OSBL: Non-metallic Valves, Fittings MHrs | SA1: OSBL: Specialty Piping Items MHrs | SB1: OSBL: Firewater Piping MHrs | SC1: OSBL: Ductwork, Launders MHrs | SD1: OSBL: Pipelines MHrs | SE1: OSBL: Other Piping MHrs | SF1: OSBL: Pipe Testing MHrs | SG1: OSBL: Pipe Demolition MHrs | SH1: OSBL: Above Ground (AG) Piping MHrs | SI1: OSBL: Underground (UG) Piping MHrs | SJ1: OSBL: Extra-small Diameter MHrs | SK1: OSBL: Small Diameter MHrs | SL1: OSBL: Medium Diameter MHrs | SM1: OSBL: Large Diameter MHrs | SN1: OSBL: Extra-large Diameter MHrs | SO1: ISBL: Earthwork MHrs | SP1: ISBL: Roads, Railroads MHrs | SQ1: ISBL: Piling MHrs | SR1: ISBL: Paving MHrs | SS1: ISBL: Concrete MHrs | ST1: ISBL: Grout MHrs | SU1: ISBL: Rebar MHrs | SV1: ISBL: Buildings, Architectural MHrs | SW1: ISBL: Other Sitework MHrs | SX1: ISBL: Other Civil MHrs | SY1: ISBL: Civil Demolition MHrs | SZ1: OSBL: Earthwork MHrs | TA1: OSBL: Roads, Railroads MHrs | TB1: OSBL: Piling MHrs | TC1: OSBL: Paving MHrs | TD1: OSBL: Concrete MHrs | TE1: OSBL: Grout MHrs | TF1: OSBL: Rebar MHrs | TG1: OSBL: Buildings, Architectural MHrs | TH1: OSBL: Other Sitework MHrs | TI1: OSBL: Other Civil MHrs | TJ1: OSBL: Civil Demolition MHrs | TK1: ISBL: Extra Light Steel MHrs | TL1: ISBL: Light Steel MHrs | TM1: ISBL: Medium Steel MHrs | TN1: ISBL: Heavy Steel MHrs | TO1: ISBL: Extra Heavy Steel MHrs | TP1: ISBL: Offshore Steel MHrs | TQ1: ISBL: Other Steel Items MHrs | TR1: ISBL: Steel Demolition MHrs | TS1: OSBL: Extra Light Steel MHrs | TT1: OSBL: Light Steel MHrs | TU1: OSBL: Medium Steel MHrs | TV1: OSBL: Heavy Steel MHrs | TW1: OSBL: Extra Heavy Steel MHrs | TX1: OSBL: Offshore Steel MHrs | TY1: OSBL: Other Steel Items MHrs | TZ1: OSBL: Steel Demolition MHrs | UA1: ISBL: Sensors MHrs | UB1: ISBL: Control Valves MHrs | UC1: ISBL: Wiring, Cable, Data Highway, Fiber Optic MHrs | UD1: ISBL: Junction Boxes, Cabinets Etc. MHrs | UE1: ISBL: Instru. Conduit, Fittings MHrs | UF1: ISBL: Instru. Cable Tray, Supports MHrs | UG1: ISBL: Computer Control MHrs | UH1: ISBL: Instrument Testing MHrs | UI1: ISBL: Other Instrumentation Items MHrs | UJ1: ISBL: Instrumentation Demolition MHrs | UK1: OSBL: Sensors MHrs | UL1: OSBL: Control Valves MHrs | UM1: OSBL: Wiring, Cable, Data Highway, Fiber Optic MHrs | UN1: OSBL: Junction Boxes, Cabinets Etc. MHrs | UO1: OSBL: Instru. Conduit, Fittings MHrs | UP1: OSBL: Instru. Cable Tray, Supports MHrs | UQ1: OSBL: Computer Control MHrs | UR1: OSBL: Instrument Testing MHrs | US1: OSBL: Other Instrumentation Items MHrs | UT1: OSBL: Instrumentation Demolition MHrs | UU1: ISBL: HV Electrical Cable MHrs | UV1: ISBL: MV Electrical Cable MHrs | UW1: ISBL: LV Electrical Cable MHrs | UX1: ISBL: Control Cable MHrs | UY1: ISBL: Lighting Cable MHrs | UZ1: ISBL: Elec. Conduit, Fittings MHrs | VA1: ISBL: Elec. Cable Tray, Supports MHrs | VB1: ISBL: Transformers, Switchgear MHrs | VC1: ISBL: Motor Control Center MHrs | VD1: ISBL: Other Electrical Equip. MHrs | VE1: ISBL: Other Electrical Items MHrs | VF1: ISBL: Electrical Testing MHrs | VG1: ISBL: Electrical Demolition MHrs | VH1: ISBL: Above Ground Electrical MHrs | VI1: ISBL: Below Ground Electrical MHrs | VJ1: OSBL: HV Electrical Cable MHrs | VK1: OSBL: MV Electrical Cable MHrs | VL1: OSBL: LV Electrical Cable MHrs | VM1: OSBL: Control Cable MHrs | VN1: OSBL: Lighting Cable MHrs | VO1: OSBL: Elec. Conduit, Fittings MHrs | VP1: OSBL: Elec. Cable Tray, Supports MHrs | VQ1: OSBL: Transformers, Switchgear MHrs | VR1: OSBL: Motor Control Center MHrs | VS1: OSBL: Other Electrical Equip. MHrs | VT1: OSBL: Other Electrical Items MHrs | VU1: OSBL: Electrical Testing MHrs | VV1: OSBL: Electrical Demolition MHrs | VW1: OSBL: Above Ground Electrical MHrs | VX1: OSBL: Below Ground Electrical MHrs | VY1: ISBL: Equipment Insulation MHrs | VZ1: ISBL: Pipe Insulation MHrs | WA1: ISBL: Equipment Fireproofing MHrs | WB1: ISBL: Steel Fireproofing MHrs | WC1: ISBL: Other Insulation, Fireproofing MHrs | WD1: ISBL: Insulation, Fireproofing Demolition MHrs | WE1: OSBL: Equipment Insulation MHrs | WF1: OSBL: Pipe Insulation MHrs | WG1: OSBL: Equipment Fireproofing MHrs | WH1: OSBL: Steel Fireproofing MHrs | WI1: OSBL: Other Insulation, Fireproofing MHrs | WJ1: OSBL: Insulation, Fireproofing Demolition MHrs | WK1: ISBL: Equipment Paint MHrs | WL1: ISBL: Pipe Paint MHrs | WM1: ISBL: Steel Paint MHrs | WN1: ISBL: Surface Preparation MHrs | WO1: ISBL: Module Paint MHrs | WP1: ISBL: Other Paint MHrs | WQ1: ISBL: Paint Demolition MHrs | WR1: OSBL: Equipment Paint MHrs | WS1: OSBL: Pipe Paint MHrs | WT1: OSBL: Steel Paint MHrs | WU1: OSBL: Surface Preparation MHrs | WV1: OSBL: Module Paint MHrs | WW1: OSBL: Other Paint MHrs | WX1: OSBL: Paint Demolition MHrs | WY1: ISBL: Boiler Plant Equip. Labor Cost | WZ1: ISBL: Centrifugal Compressors Labor Cost | XA1: ISBL: Crushers, Mills Labor Cost | XB1: ISBL: Drivers Labor Cost | XC1: ISBL: Fans, Blowers Labor Cost | XD1: ISBL: Flares Labor Cost | XE1: ISBL: Fluid Separation Equip. Labor Cost | XF1: ISBL: Furnaces, Heaters Labor Cost | XG1: ISBL: Generators Labor Cost | XH1: ISBL: Heat Exchangers Labor Cost | XI1: ISBL: Material Handling Equip. Labor Cost | XJ1: ISBL: Package Units Labor Cost | XK1: ISBL: Process Vessels Labor Cost | XL1: ISBL: Pumps Labor Cost | XM1: ISBL: Reactors, Mixers Labor Cost | XN1: ISBL: Reciprocating Compressors Labor Cost | XO1: ISBL: Solids Separation Equip. Labor Cost | XP1: ISBL: Storage Vessels Labor Cost | XQ1: ISBL: Turbo Expanders Labor Cost | XR1: ISBL: Other Equipment Items Labor Cost | XS1: ISBL: Design Allowance Labor Cost | XT1: ISBL: Warehouse Spares Labor Cost | XU1: ISBL: Equipment Demolition Labor Cost | XV1: OSBL: Boiler Plant Equip. Labor Cost | XW1: OSBL: Centrifugal Compressors Labor Cost | XX1: OSBL: Crushers, Mills Labor Cost | XY1: OSBL: Drivers Labor Cost | XZ1: OSBL: Fans, Blowers Labor Cost | YA1: OSBL: Flares Labor Cost | YB1: OSBL: Fluid Separation Equip. Labor Cost | YC1: OSBL: Furnaces, Heaters Labor Cost | YD1: OSBL: Generators Labor Cost | YE1: OSBL: Heat Exchangers Labor Cost | YF1: OSBL: Material Handling Equip. Labor Cost | YG1: OSBL: Package Units Labor Cost | YH1: OSBL: Process Vessels Labor Cost | YI1: OSBL: Pumps Labor Cost | YJ1: OSBL: Reactors, Mixers Labor Cost | YK1: OSBL: Reciprocating Compressors Labor Cost | YL1: OSBL: Solids Separation Equip. Labor Cost | YM1: OSBL: Storage Vessels Labor Cost | YN1: OSBL: Turbo Expanders Labor Cost | YO1: OSBL: Other Equipment Items Labor Cost | YP1: OSBL: Design Allowance Labor Cost | YQ1: OSBL: Warehouse Spares Labor Cost | YR1: OSBL: Equipment Demolition Labor Cost | YS1: ISBL: CS Pipe Labor Cost | YT1: ISBL: CS Valves, Fittings Labor Cost | YU1: ISBL: SS Pipe Labor Cost | YV1: ISBL: SS Valves, Fittings Labor Cost | YW1: ISBL: Non-ferrous Pipe Labor Cost | YX1: ISBL: Non-ferrous Valves, Fittings Labor Cost | YY1: ISBL: Lined Pipe Labor Cost | YZ1: ISBL: Lined Valves, Fittings Labor Cost | ZA1: ISBL: Non-metallic Pipe Labor Cost | ZB1: ISBL: Non-metallic Valves, Fittings Labor Cost | ZC1: ISBL: Specialty Piping Items Labor Cost | ZD1: ISBL: Firewater Piping Labor Cost | ZE1: ISBL: Ductwork, Launders Labor Cost | ZF1: ISBL: Pipelines Labor Cost | ZG1: ISBL: Other Piping Labor Cost | ZH1: ISBL: Pipe Testing Labor Cost | ZI1: ISBL: Pipe Demolition Labor Cost | ZJ1: ISBL: Above Ground (AG) Piping Labor Cost | ZK1: ISBL: Underground (UG) Piping Labor Cost | ZL1: ISBL: Extra-small Diameter Labor Cost | ZM1: ISBL: Small Diameter Labor Cost | ZN1: ISBL: Medium Diameter Labor Cost | ZO1: ISBL: Large Diameter Labor Cost | ZP1: ISBL: Extra-large Diameter Labor Cost | ZQ1: OSBL: CS Pipe Labor Cost | ZR1: OSBL: CS Valves, Fittings Labor Cost | ZS1: OSBL: SS Pipe Labor Cost | ZT1: OSBL: SS Valves, Fittings Labor Cost | ZU1: OSBL: Non-ferrous Pipe Labor Cost | ZV1: OSBL: Non-ferrous Valves, Fittings Labor Cost | ZW1: OSBL: Lined Pipe Labor Cost | ZX1: OSBL: Lined Valves, Fittings Labor Cost | ZY1: OSBL: Non-metallic Pipe Labor Cost | ZZ1: OSBL: Non-metallic Valves, Fittings Labor Cost | AAA1: OSBL: Specialty Piping Items Labor Cost | AAB1: OSBL: Firewater Piping Labor Cost | AAC1: OSBL: Ductwork, Launders Labor Cost | AAD1: OSBL: Pipelines Labor Cost | AAE1: OSBL: Other Piping Labor Cost | AAF1: OSBL: Pipe Testing Labor Cost | AAG1: OSBL: Pipe Demolition Labor Cost | AAH1: OSBL: Above Ground (AG) Piping Labor Cost | AAI1: OSBL: Underground (UG) Piping Labor Cost | AAJ1: OSBL: Extra-small Diameter Labor Cost | AAK1: OSBL: Small Diameter Labor Cost | AAL1: OSBL: Medium Diameter Labor Cost | AAM1: OSBL: Large Diameter Labor Cost | AAN1: OSBL: Extra-large Diameter Labor Cost | AAO1: ISBL: Earthwork Labor Cost | AAP1: ISBL: Roads, Railroads Labor Cost | AAQ1: ISBL: Piling Labor Cost | AAR1: ISBL: Paving Labor Cost | AAS1: ISBL: Concrete Labor Cost | AAT1: ISBL: Grout Labor Cost | AAU1: ISBL: Rebar Labor Cost | AAV1: ISBL: Buildings, Architectural Labor Cost | AAW1: ISBL: Other Sitework Labor Cost | AAX1: ISBL: Other Civil Labor Cost | AAY1: ISBL: Civil Demolition Labor Cost | AAZ1: OSBL: Earthwork Labor Cost | ABA1: OSBL: Roads, Railroads Labor Cost | ABB1: OSBL: Piling Labor Cost | ABC1: OSBL: Paving Labor Cost | ABD1: OSBL: Concrete Labor Cost | ABE1: OSBL: Grout Labor Cost | ABF1: OSBL: Rebar Labor Cost | ABG1: OSBL: Buildings, Architectural Labor Cost | ABH1: OSBL: Other Sitework Labor Cost | ABI1: OSBL: Other Civil Labor Cost | ABJ1: OSBL: Civil Demolition Labor Cost | ABK1: ISBL: Extra Light Steel Labor Cost | ABL1: ISBL: Light Steel Labor Cost | ABM1: ISBL: Medium Steel Labor Cost | ABN1: ISBL: Heavy Steel Labor Cost | ABO1: ISBL: Extra Heavy Steel Labor Cost | ABP1: ISBL: Offshore Steel Labor Cost | ABQ1: ISBL: Other Steel Items Labor Cost | ABR1: ISBL: Steel Demolition Labor Cost | ABS1: OSBL: Extra Light Steel Labor Cost | ABT1: OSBL: Light Steel Labor Cost | ABU1: OSBL: Medium Steel Labor Cost | ABV1: OSBL: Heavy Steel Labor Cost | ABW1: OSBL: Extra Heavy Steel Labor Cost | ABX1: OSBL: Offshore Steel Labor Cost | ABY1: OSBL: Other Steel Items Labor Cost | ABZ1: OSBL: Steel Demolition Labor Cost | ACA1: ISBL: Sensors Labor Cost | ACB1: ISBL: Control Valves Labor Cost | ACC1: ISBL: Wiring, Cable, Data Highway, Fiber Optic Labor Cost | ACD1: ISBL: Junction Boxes, Cabinets Etc. Labor Cost | ACE1: ISBL: Instru. Conduit, Fittings Labor Cost | ACF1: ISBL: Instru. Cable Tray, Supports Labor Cost | ACG1: ISBL: Computer Control Labor Cost | ACH1: ISBL: Instrument Testing Labor Cost | ACI1: ISBL: Other Instrumentation Items Labor Cost | ACJ1: ISBL: Instrumentation Demolition Labor Cost | ACK1: OSBL: Sensors Labor Cost | ACL1: OSBL: Control Valves Labor Cost | ACM1: OSBL: Wiring, Cable, Data Highway, Fiber Optic Labor Cost | ACN1: OSBL: Junction Boxes, Cabinets Etc. Labor Cost | ACO1: OSBL: Instru. Conduit, Fittings Labor Cost | ACP1: OSBL: Instru. Cable Tray, Supports Labor Cost | ACQ1: OSBL: Computer Control Labor Cost | ACR1: OSBL: Instrument Testing Labor Cost | ACS1: OSBL: Other Instrumentation Items Labor Cost | ACT1: OSBL: Instrumentation Demolition Labor Cost | ACU1: ISBL: HV Electrical Cable Labor Cost | ACV1: ISBL: MV Electrical Cable Labor Cost | ACW1: ISBL: LV Electrical Cable Labor Cost | ACX1: ISBL: Control Cable Labor Cost | ACY1: ISBL: Lighting Cable Labor Cost | ACZ1: ISBL: Elec. Conduit, Fittings Labor Cost | ADA1: ISBL: Elec. Cable Tray, Supports Labor Cost | ADB1: ISBL: Transformers, Switchgear Labor Cost | ADC1: ISBL: Motor Control Center Labor Cost | ADD1: ISBL: Other Electrical Equip. Labor Cost | ADE1: ISBL: Other Electrical Items Labor Cost | ADF1: ISBL: Electrical Testing Labor Cost | ADG1: ISBL: Electrical Demolition Labor Cost | ADH1: ISBL: Above Ground Electrical Labor Cost | ADI1: ISBL: Below Ground Electrical Labor Cost | ADJ1: OSBL: HV Electrical Cable Labor Cost | ADK1: OSBL: MV Electrical Cable Labor Cost | ADL1: OSBL: LV Electrical Cable Labor Cost | ADM1: OSBL: Control Cable Labor Cost | ADN1: OSBL: Lighting Cable Labor Cost | ADO1: OSBL: Elec. Conduit, Fittings Labor Cost | ADP1: OSBL: Elec. Cable Tray, Supports Labor Cost | ADQ1: OSBL: Transformers, Switchgear Labor Cost | ADR1: OSBL: Motor Control Center Labor Cost | ADS1: OSBL: Other Electrical Equip. Labor Cost | ADT1: OSBL: Other Electrical Items Labor Cost | ADU1: OSBL: Electrical Testing Labor Cost | ADV1: OSBL: Electrical Demolition Labor Cost | ADW1: OSBL: Above Ground Electrical Labor Cost | ADX1: OSBL: Below Ground Electrical Labor Cost | ADY1: ISBL: Equipment Insulation Labor Cost | ADZ1: ISBL: Pipe Insulation Labor Cost | AEA1: ISBL: Equipment Fireproofing Labor Cost | AEB1: ISBL: Steel Fireproofing Labor Cost | AEC1: ISBL: Other Insulation, Fireproofing Labor Cost | AED1: ISBL: Insulation, Fireproofing Demolition Labor Cost | AEE1: OSBL: Equipment Insulation Labor Cost | AEF1: OSBL: Pipe Insulation Labor Cost | AEG1: OSBL: Equipment Fireproofing Labor Cost | AEH1: OSBL: Steel Fireproofing Labor Cost | AEI1: OSBL: Other Insulation, Fireproofing Labor Cost | AEJ1: OSBL: Insulation, Fireproofing Demolition Labor Cost | AEK1: ISBL: Equipment Paint Labor Cost | AEL1: ISBL: Pipe Paint Labor Cost | AEM1: ISBL: Steel Paint Labor Cost | AEN1: ISBL: Surface Preparation Labor Cost | AEO1: ISBL: Module Paint Labor Cost | AEP1: ISBL: Other Paint Labor Cost | AEQ1: ISBL: Paint Demolition Labor Cost | AER1: OSBL: Equipment Paint Labor Cost | AES1: OSBL: Pipe Paint Labor Cost | AET1: OSBL: Steel Paint Labor Cost | AEU1: OSBL: Surface Preparation Labor Cost | AEV1: OSBL: Module Paint Labor Cost | AEW1: OSBL: Other Paint Labor Cost | AEX1: OSBL: Paint Demolition Labor Cost | AEY1: Indirects: Fringe Benefits MHrs | AEZ1: Indirects: Burdens MHrs | AFA1: Indirects: Consumables, Small Tools MHrs | AFB1: Indirects: Miscellaneous, Insurance, Etc. MHrs | AFC1: Indirects: Scaffolding MHrs | AFD1: Indirects: Equipment Rental MHrs | AFE1: Indirects: Vendor Reps MHrs | AFF1: Indirects: Field Services MHrs | AFG1: Indirects: Temp Const, Utilities MHrs | AFH1: Indirects: Mobilization/Demobilization MHrs | AFI1: Indirects: Camp, Catering MHrs | AFJ1: Indirects: Travel MHrs | AFK1: Indirects: Overtime Premium MHrs | AFL1: Indirects: Lump Sum Construction Indirect MHrs | AFM1: Indirects: Field Const Supv MHrs | AFN1: Indirects: Start-up, Commissioning MHrs | AFO1: Indirects: Lump Sum Engineering MHrs | AFP1: Indirects: Basic Engineering MHrs | AFQ1: Indirects: Detail Engineering MHrs | AFR1: Indirects: Material Procurement MHrs | AFS1: Indirects: Subcontract Procurement MHrs | AFT1: Indirects: Engineering Management MHrs | AFU1: Indirects: Lump Sum Freight MHrs | AFV1: Indirects: Domestic Freight MHrs | AFW1: Indirects: Ocean Freight MHrs | AFX1: Indirects: Air Freight MHrs | AFY1: Indirects: Module Freight MHrs | AFZ1: Indirects: Other Freight MHrs | AGA1: Indirects: Lump Sum Taxes, Permits MHrs | AGB1: Indirects: Permits MHrs | AGC1: Indirects: Materials Taxes MHrs | AGD1: Indirects: Construction Taxes MHrs | AGE1: Indirects: Engineering Taxes MHrs | AGF1: Indirects: Other Taxes MHrs | AGG1: Indirects: Lump Sum Const Mgmt MHrs | AGH1: Indirects: Home Office Const Supp MHrs | AGI1: Indirects: Construction Management MHrs | AGJ1: Indirects: G and A Overheads MHrs | AGK1: Indirects: Contract Fee MHrs | AGL1: Indirects: Royalty, Misc Charges MHrs | AGM1: Indirects: Escalation MHrs | AGN1: Indirects: Contingency MHrs | AGO1: Indirects: Fringe Benefits Cost | AGP1: Indirects: Burdens Cost | AGQ1: Indirects: Consumables, Small Tools Cost | AGR1: Indirects: Miscellaneous, Insurance, Etc. Cost | AGS1: Indirects: Scaffolding Cost | AGT1: Indirects: Equipment Rental Cost | AGU1: Indirects: Vendor Reps Cost | AGV1: Indirects: Field Services Cost | AGW1: Indirects: Temp Const, Utilities Cost | AGX1: Indirects: Mobilization/Demobilization Cost | AGY1: Indirects: Camp, Catering Cost | AGZ1: Indirects: Travel Cost | AHA1: Indirects: Overtime Premium Cost | AHB1: Indirects: Lump Sum Construction Indirect Cost | AHC1: Indirects: Field Const Supv Cost | AHD1: Indirects: Start-up, Commissioning Cost | AHE1: Indirects: Lump Sum Engineering Cost | AHF1: Indirects: Basic Engineering Cost | AHG1: Indirects: Detail Engineering Cost | AHH1: Indirects: Material Procurement Cost | AHI1: Indirects: Subcontract Procurement Cost | AHJ1: Indirects: Engineering Management Cost | AHK1: Indirects: Lump Sum Freight Cost | AHL1: Indirects: Domestic Freight Cost | AHM1: Indirects: Ocean Freight Cost | AHN1: Indirects: Air Freight Cost | AHO1: Indirects: Module Freight Cost | AHP1: Indirects: Other Freight Cost | AHQ1: Indirects: Lump Sum Taxes, Permits Cost | AHR1: Indirects: Permits Cost | AHS1: Indirects: Materials Taxes Cost | AHT1: Indirects: Construction Taxes Cost | AHU1: Indirects: Engineering Taxes Cost | AHV1: Indirects: Other Taxes Cost | AHW1: Indirects: Lump Sum Const Mgmt Cost | AHX1: Indirects: Home Office Const Supp Cost | AHY1: Indirects: Construction Management Cost | AHZ1: Indirects: G and A Overheads Cost | AIA1: Indirects: Contract Fee Cost | AIB1: Indirects: Royalty, Misc Charges Cost | AIC1: Indirects: Escalation Cost | AID1: Indirects: Contingency Cost | AIE1: UoM: Equipment Count | AIF1: UoM: Pipe Length | AIG1: UoM: Earthwork | AIH1: UoM: Roads, Railroads | AII1: UoM: Paving | AIJ1: UoM: Concrete, Grout | AIK1: UoM: Steel, Rebar | AIL1: UoM: Electrical Wire Length | AIM1: UoM: Instrumentation Wire Length | AIN1: UoM: Equipment Insulation | AIO1: UoM: Pipe Insulation | AIP1: UoM: Equipment Fireproofing | AIQ1: UoM: Steel Fireproofing | AIR1: UoM: Paint Area
